Workbook

Sheet Master
C2: Games | D2: Win | E2: Loss | F2: %
B3: Picks | C3: =COUNTA(N9:N1000) -> 194 | D3: =SUM(N9:N1000) -> 120 | E3: =C3-D3 -> 74 | F3: =D3/C3 -> 0.6185567
B4: ATS | C4: =COUNTA(V9:V1000) -> 123 | D4: =SUM(V9:V1000) -> 65 | E4: =C4-D4 -> 58 | F4: =D4/C4 -> 0.52845528
B5: Totals | C5: =COUNTA(AB9:AB1000) -> 123 | D5: =SUM(AB9:AB1000) -> 56 | E5: =C5-D5 -> 67 | F5: =D5/C5 -> 0.45528455
H7: Game Picks (Win Prob) | O7: Pred Score (Score Model) | Q7: Spread Picks (Score Model) | W7: Total Picks (Score Model) | AC7: home_epa | AF7: away_epa
B8: season | C8: week | D8: home_team | E8: away_team | F8: home_score | G8: away_score | H8: prob_home | I8: home_team_ml | J8: prob_away | K8: away_team_ml | L8: pred | M8: winner | N8: winner_correct? | O8: home | P8: away | Q8: spread_line | R8: pred_spread | S8: spread_pick | T8: result | U8: spread_result | V8: spread_correct? | W8: total_line | X8: pred_total | Y8: total_pick | Z8: total | AA8: total_result | AB8: total_correct? | AC8: EPA_O_Play | AD8: EPA_D_Play | AE8: EPA_ST_Play | AF8: EPA_O_Play | AG8: EPA_D_Play | AH8: EPA_ST_Play
B9: 2025 | C9: 6 | D9: NYG | E9: PHI | H9: 0.28413917 | I9: +251 | J9: 0.71586083 | K9: -251 | L9: PHI | M9: NYG | N9: =IF(M9=L9,1,0) -> 0 | AC9: 0.25124221 | AD9: 0.066168526 | AE9: -0.027362438 | AF9: -0.066168526 | AG9: -0.25124221 | AH9: 0.027362438
B10: 2025 | C10: 6 | D10: NYJ | E10: DEN | H10: 0.30012096 | I10: +233 | J10: 0.69987904 | K10: -233 | L10: DEN | M10: DEN | N10: =IF(M10=L10,1,0) -> 1 | AC10: -0.43215489 | AD10: 0.16995373 | AE10: 0.34083964 | AF10: -0.16995373 | AG10: 0.43215489 | AH10: -0.34083964
B11: 2025 | C11: 6 | D11: BAL | E11: LA | H11: 0.53913174 | I11: -116 | J11: 0.46086826 | K11: +116 | L11: BAL | M11: LA | N11: =IF(M11=L11,1,0) -> 0 | AC11: -0.29375997 | AD11: -0.015975545 | AE11: 0.37059372 | AF11: 0.015975545 | AG11: 0.29375997 | AH11: -0.37059372
B12: 2025 | C12: 6 | D12: CAR | E12: DAL | H12: 0.49133873 | I12: +103 | J12: 0.50866127 | K12: -103 | L12: DAL | M12: CAR | N12: =IF(M12=L12,1,0) -> 0 | AC12: 0.17789871 | AD12: -0.2027874 | AE12: 0.024269279 | AF12: 0.2027874 | AG12: -0.17789871 | AH12: -0.024269279
B13: 2025 | C13: 6 | D13: IND | E13: ARI | H13: 0.58161291 | I13: -139 | J13: 0.41838709 | K13: +139 | L13: IND | M13: IND | N13: =IF(M13=L13,1,0) -> 1 | AC13: 0.15875688 | AD13: -0.073672771 | AE13: -0.062292337 | AF13: 0.073672771 | AG13: -0.15875688 | AH13: 0.062292337
B14: 2025 | C14: 6 | D14: JAX | E14: SEA | H14: 0.46542939 | I14: +114 | J14: 0.53457061 | K14: -114 | L14: SEA | M14: SEA | N14: =IF(M14=L14,1,0) -> 1 | AC14: -0.082264423 | AD14: -0.020928413 | AE14: -0.20806897 | AF14: 0.020928413 | AG14: 0.082264423 | AH14: 0.20806897
B15: 2025 | C15: 6 | D15: MIA | E15: LAC | H15: 0.4933361 | I15: +102 | J15: 0.5066639 | K15: -102 | L15: LAC | M15: LAC | N15: =IF(M15=L15,1,0) -> 1 | AC15: 0.038278063 | AD15: -0.0617472 | AE15: -0.013840508 | AF15: 0.0617472 | AG15: -0.038278063 | AH15: 0.013840508
B16: 2025 | C16: 6 | D16: NO | E16: NE | H16: 0.39499877 | I16: +153 | J16: 0.60500123 | K16: -153 | L16: NE | M16: NE | N16: =IF(M16=L16,1,0) -> 1 | AC16: -0.073139174 | AD16: -0.13044801 | AE16: 0.13509109 | AF16: 0.13044801 | AG16: 0.073139174 | AH16: -0.13509109
B17: 2025 | C17: 6 | D17: PIT | E17: CLE | H17: 0.71805668 | I17: -254 | J17: 0.28194332 | K17: +254 | L17: PIT | M17: PIT | N17: =IF(M17=L17,1,0) -> 1 | AC17: 0.095861427 | AD17: 0.13702202 | AE17: -0.14666659 | AF17: -0.13702202 | AG17: -0.095861427 | AH17: 0.14666659
B18: 2025 | C18: 6 | D18: LV | E18: TEN | H18: 0.60215188 | I18: -151 | J18: 0.39784812 | K18: +151 | L18: LV | M18: LV | N18: =IF(M18=L18,1,0) -> 1 | AC18: -0.097661511 | AD18: 0.24401585 | AE18: 0.19498157 | AF18: -0.24401585 | AG18: 0.097661511 | AH18: -0.19498157
B19: 2025 | C19: 6 | D19: GB | E19: CIN | H19: 0.72152836 | I19: -259 | J19: 0.27847164 | K19: +259 | L19: GB | M19: GB | N19: =IF(M19=L19,1,0) -> 1 | AC19: 0.21342839 | AD19: -0.10244938 | AE19: 0.089890928 | AF19: 0.10244938 | AG19: -0.21342839 | AH19: -0.089890928
B20: 2025 | C20: 6 | D20: TB | E20: SF | H20: 0.59882672 | I20: -149 | J20: 0.40117328 | K20: +149 | L20: TB | M20: TB | N20: =IF(M20=L20,1,0) -> 1 | AC20: 0.24584 | AD20: 0.11939343 | AE20: -0.28655228 | AF20: -0.11939343 | AG20: -0.24584 | AH20: 0.28655228
B21: 2025 | C21: 6 | D21: KC | E21: DET | H21: 0.36153707 | I21: +176 | J21: 0.63846293 | K21: -176 | L21: DET | M21: KC | N21: =IF(M21=L21,1,0) -> 0 | AC21: 0.31075544 | AD21: -0.08266475 | AE21: -0.0042046241 | AF21: 0.08266475 | AG21: -0.31075544 | AH21: 0.0042046241
B22: 2025 | C22: 6 | D22: ATL | E22: BUF | H22: 0.31839251 | I22: +214 | J22: 0.68160749 | K22: -214 | L22: BUF | M22: ATL | N22: =IF(M22=L22,1,0) -> 0 | AC22: 0.10814126 | AD22: 0.10416144 | AE22: -0.1186255 | AF22: -0.10416144 | AG22: -0.10814126 | AH22: 0.1186255
B23: 2025 | C23: 6 | D23: WAS | E23: CHI | H23: 0.73154658 | I23: -272 | J23: 0.26845342 | K23: +272 | L23: WAS | M23: CHI | N23: =IF(M23=L23,1,0) -> 0 | AC23: 0.018111467 | AD23: -0.1277509 | AE23: 0.071527021 | AF23: 0.1277509 | AG23: -0.018111467 | AH23: -0.071527021
B24: 2025 | C24: 7 | D24: CIN | E24: PIT | H24: 0.48091506 | I24: +107 | J24: 0.51908494 | K24: -107 | L24: PIT | M24: CIN | N24: 0 | AC24: 0.28925643 | AD24: -0.27371408 | AE24: -0.076034888 | AF24: 0.27371408 | AG24: -0.28925643 | AH24: 0.076034888
B25: 2025 | C25: 7 | D25: JAX | E25: LA | H25: 0.46977703 | I25: +112 | J25: 0.53022297 | K25: -112 | L25: LA | M25: LA | N25: 1 | AC25: -0.1461088 | AD25: -0.23843634 | AE25: -0.20178508 | AF25: 0.23843634 | AG25: 0.1461088 | AH25: 0.20178508
B26: 2025 | C26: 7 | D26: CHI | E26: NO | H26: 0.58504581 | I26: -140 | J26: 0.41495419 | K26: +140 | L26: CHI | M26: CHI | N26: 1 | AC26: 0.01348116 | AD26: 0.22400876 | AE26: 0.19784313 | AF26: -0.22400876 | AG26: -0.01348116 | AH26: -0.19784313
B27: 2025 | C27: 7 | D27: CLE | E27: MIA | H27: 0.33682566 | I27: +196 | J27: 0.66317434 | K27: -196 | L27: MIA | M27: CLE | N27: 0 | AC27: -0.017893693 | AD27: 0.51155989 | AE27: 0.063372169 | AF27: -0.51155989 | AG27: 0.017893693 | AH27: -0.063372169
B28: 2025 | C28: 7 | D28: KC | E28: LV | H28: 0.76251043 | I28: -321 | J28: 0.23748957 | K28: +321 | L28: KC | M28: KC | N28: 1 | AC28: 0.2171731 | AD28: 0.62946069 | AE28: -0.24452791 | AF28: -0.62946069 | AG28: -0.2171731 | AH28: 0.24452791
B29: 2025 | C29: 7 | D29: MIN | E29: PHI | H29: 0.46008668 | I29: +117 | J29: 0.53991332 | K29: -117 | L29: PHI | M29: PHI | N29: 1 | AC29: -0.088495227 | AD29: -0.20847946 | AE29: 0.33452468 | AF29: 0.20847946 | AG29: 0.088495227 | AH29: -0.33452468
B30: 2025 | C30: 7 | D30: NYJ | E30: CAR | H30: 0.43942513 | I30: +127 | J30: 0.56057487 | K30: -127 | L30: CAR | M30: CAR | N30: 1 | AC30: -0.26674719 | AD30: 0.085645286 | AE30: -0.11531259 | AF30: -0.085645286 | AG30: 0.26674719 | AH30: 0.11531259
B31: 2025 | C31: 7 | D31: TEN | E31: NE | H31: 0.31228555 | I31: +220 | J31: 0.68771445 | K31: -220 | L31: NE | M31: NE | N31: 1 | AC31: -0.28472243 | AD31: -0.24146947 | AE31: 0.26711339 | AF31: 0.24146947 | AG31: 0.28472243 | AH31: -0.26711339
B32: 2025 | C32: 7 | D32: DEN | E32: NYG | H32: 0.74988507 | I32: -299 | J32: 0.25011493 | K32: +299 | L32: DEN | M32: DEN | N32: 1 | AC32: 0.11573301 | AD32: -0.19457486 | AE32: 0.097547495 | AF32: 0.19457486 | AG32: -0.11573301 | AH32: -0.097547495
B33: 2025 | C33: 7 | D33: LAC | E33: IND | H33: 0.4904864 | I33: +103 | J33: 0.5095136 | K33: -103 | L33: IND | M33: IND | N33: 1 | AC33: 0.096067357 | AD33: -0.44475957 | AE33: -0.15667809 | AF33: 0.44475957 | AG33: -0.096067357 | AH33: 0.15667809
B34: 2025 | C34: 7 | D34: ARI | E34: GB | H34: 0.42954545 | I34: +132 | J34: 0.57045455 | K34: -132 | L34: GB | M34: GB | N34: 1 | AC34: -0.0025914829 | AD34: -0.11835686 | AE34: 0.052370644 | AF34: 0.11835686 | AG34: 0.0025914829 | AH34: -0.052370644
B35: 2025 | C35: 7 | D35: DAL | E35: WAS | H35: 0.45455863 | I35: +119 | J35: 0.54544137 | K35: -119 | L35: WAS | M35: DAL | N35: 0 | AC35: 0.15809155 | AD35: 0.19612538 | AE35: 0.031338125 | AF35: -0.19612538 | AG35: -0.15809155 | AH35: -0.031338125
B36: 2025 | C36: 7 | D36: SF | E36: ATL | H36: 0.50845245 | I36: -103 | J36: 0.49154755 | K36: +103 | L36: SF | M36: SF | N36: 1 | AC36: 0.0394085 | AD36: 0.12123582 | AE36: 0.039254677 | AF36: -0.12123582 | AG36: -0.0394085 | AH36: -0.039254677
B37: 2025 | C37: 7 | D37: DET | E37: TB | H37: 0.58751521 | I37: -142 | J37: 0.41248479 | K37: +142 | L37: DET | M37: DET | N37: 1 | AC37: -0.099057456 | AD37: 0.35557553 | AE37: -0.024791638 | AF37: -0.35557553 | AG37: 0.099057456 | AH37: 0.024791638
B38: 2025 | C38: 7 | D38: SEA | E38: HOU | H38: 0.61141525 | I38: -157 | J38: 0.38858475 | K38: +157 | L38: SEA | M38: SEA | N38: 1 | AC38: -0.23093883 | AD38: 0.32778671 | AE38: 0.043519257 | AF38: -0.32778671 | AG38: 0.23093883 | AH38: -0.043519257
B39: 2025 | C39: 8 | D39: LAC | E39: MIN | H39: 0.536 | I39: -120 | J39: 0.464 | K39: +120 | L39: LAC | M39: LAC | N39: 1 | AC39: 0.20573016 | AD39: 0.33306915 | AE39: -0.013063612 | AF39: -0.33306915 | AG39: -0.20573016 | AH39: 0.013063612
B40: 2025 | C40: 8 | D40: ATL | E40: MIA | H40: 0.586 | I40: -144 | J40: 0.414 | K40: +144 | L40: ATL | M40: MIA | N40: 0 | AC40: -0.30089874 | AD40: -0.13344567 | AE40: -0.14619972 | AF40: 0.13344567 | AG40: 0.30089874 | AH40: 0.14619972
B41: 2025 | C41: 8 | D41: BAL | E41: CHI | H41: 0.61263916 | I41: -158 | J41: 0.38736084 | K41: +158 | L41: BAL | M41: BAL | N41: 1 | AC41: 0.20792883 | AD41: -0.017090889 | AE41: 0.084218423 | AF41: 0.017090889 | AG41: -0.20792883 | AH41: -0.084218423
B42: 2025 | C42: 8 | D42: CAR | E42: BUF | H42: 0.347 | I42: +204 | J42: 0.653 | K42: -204 | L42: BUF | M42: BUF | N42: 1 | AC42: -0.31306085 | AD42: -0.32291098 | AE42: 0.048412263 | AF42: 0.32291098 | AG42: 0.31306085 | AH42: -0.048412263
...

Sheet Weekly Record
B2: Picks
B3: Week | C3: Games | D3: Wins | E3: Losses | F3: %
B4: {=_xlfn.UNIQUE(_xlfn._xlws.FILTER(Master!C9:C1000,NOT(ISBLANK(Master!C9:C1000))))} -> 6 | C4: =COUNTIFS(Master!C:C,'Weekly Record'!B4) -> 15 | D4: =SUMIFS(Master!N:N, Master!C:C,'Weekly Record'!B4) -> 9 | E4: =C4-D4 -> 6 | F4: =D4/C4 -> 0.6
B5: 7 | C5: =COUNTIFS(Master!C:C,'Weekly Record'!B5) -> 15 | D5: =SUMIFS(Master!N:N, Master!C:C,'Weekly Record'!B5) -> 12 | E5: =C5-D5 -> 3 | F5: =D5/C5 -> 0.8
B6: 8 | C6: =COUNTIFS(Master!C:C,'Weekly Record'!B6) -> 13 | D6: =SUMIFS(Master!N:N, Master!C:C,'Weekly Record'!B6) -> 11 | E6: =C6-D6 -> 2 | F6: =D6/C6 -> 0.84615385
B7: 9 | C7: =COUNTIFS(Master!C:C,'Weekly Record'!B7) -> 14 | D7: =SUMIFS(Master!N:N, Master!C:C,'Weekly Record'!B7) -> 7 | E7: =C7-D7 -> 7 | F7: =D7/C7 -> 0.5
B8: 10 | C8: =COUNTIFS(Master!C:C,'Weekly Record'!B8) -> 14 | D8: =SUMIFS(Master!N:N, Master!C:C,'Weekly Record'!B8) -> 10 | E8: =C8-D8 -> 4 | F8: =D8/C8 -> 0.71428571
B9: 11 | C9: =COUNTIFS(Master!C:C,'Weekly Record'!B9) -> 15 | D9: =SUMIFS(Master!N:N, Master!C:C,'Weekly Record'!B9) -> 10 | E9: =C9-D9 -> 5 | F9: =D9/C9 -> 0.66666667
B10: 12 | C10: =COUNTIFS(Master!C:C,'Weekly Record'!B10) -> 14 | D10: =SUMIFS(Master!N:N, Master!C:C,'Weekly Record'!B10) -> 10 | E10: =C10-D10 -> 4 | F10: =D10/C10 -> 0.71428571
B11: 13 | C11: =COUNTIFS(Master!C:C,'Weekly Record'!B11) -> 16 | D11: =SUMIFS(Master!N:N, Master!C:C,'Weekly Record'!B11) -> 10 | E11: =C11-D11 -> 6 | F11: =D11/C11 -> 0.625
B12: 14 | C12: =COUNTIFS(Master!C:C,'Weekly Record'!B12) -> 14 | D12: =SUMIFS(Master!N:N, Master!C:C,'Weekly Record'!B12) -> 8 | E12: =C12-D12 -> 6 | F12: =D12/C12 -> 0.57142857
B13: 15 | C13: =COUNTIFS(Master!C:C,'Weekly Record'!B13) -> 16 | D13: =SUMIFS(Master!N:N, Master!C:C,'Weekly Record'!B13) -> 8 | E13: =C13-D13 -> 8 | F13: =D13/C13 -> 0.5
B14: 16 | C14: =COUNTIFS(Master!C:C,'Weekly Record'!B14) -> 16 | D14: =SUMIFS(Master!N:N, Master!C:C,'Weekly Record'!B14) -> 8 | E14: =C14-D14 -> 8 | F14: =D14/C14 -> 0.5
B15: 17 | C15: =COUNTIFS(Master!C:C,'Weekly Record'!B15) -> 16 | D15: =SUMIFS(Master!N:N, Master!C:C,'Weekly Record'!B15) -> 10 | E15: =C15-D15 -> 6 | F15: =D15/C15 -> 0.625
B16: 18
B17: ATS
B18: Week | C18: Games | D18: Wins | E18: Losses | F18: %
B19: {=_xlfn.UNIQUE(_xlfn._xlws.FILTER(Master!C9:C1000,NOT(ISBLANK(Master!C9:C1000))))} -> 6 | C19: =COUNTIFS(Master!C:C,'Weekly Record'!B19) -> 15 | D19: =SUMIFS(Master!V:V, Master!C:C,'Weekly Record'!B19) -> 0 | E19: =C19-D19 -> 15 | F19: =D19/C19 -> 0
B20: 7 | C20: =COUNTIFS(Master!C:C,'Weekly Record'!B20) -> 15 | D20: =SUMIFS(Master!V:V, Master!C:C,'Weekly Record'!B20) -> 0 | E20: =C20-D20 -> 15 | F20: =D20/C20 -> 0
B21: 8 | C21: =COUNTIFS(Master!C:C,'Weekly Record'!B21) -> 13 | D21: =SUMIFS(Master!V:V, Master!C:C,'Weekly Record'!B21) -> 0 | E21: =C21-D21 -> 13 | F21: =D21/C21 -> 0
B22: 9 | C22: =COUNTIFS(Master!C:C,'Weekly Record'!B22) -> 14 | D22: =SUMIFS(Master!V:V, Master!C:C,'Weekly Record'!B22) -> 0 | E22: =C22-D22 -> 14 | F22: =D22/C22 -> 0
B23: 10 | C23: =COUNTIFS(Master!C:C,'Weekly Record'!B23) -> 14 | D23: =SUMIFS(Master!V:V, Master!C:C,'Weekly Record'!B23) -> 0 | E23: =C23-D23 -> 14 | F23: =D23/C23 -> 0
B24: 11 | C24: =COUNTIFS(Master!C:C,'Weekly Record'!B24) -> 15 | D24: =SUMIFS(Master!V:V, Master!C:C,'Weekly Record'!B24) -> 6 | E24: =C24-D24 -> 9 | F24: =D24/C24 -> 0.4
B25: 12 | C25: =COUNTIFS(Master!C:C,'Weekly Record'!B25) -> 14 | D25: =SUMIFS(Master!V:V, Master!C:C,'Weekly Record'!B25) -> 8 | E25: =C25-D25 -> 6 | F25: =D25/C25 -> 0.57142857
B26: 13 | C26: =COUNTIFS(Master!C:C,'Weekly Record'!B26) -> 16 | D26: =SUMIFS(Master!V:V, Master!C:C,'Weekly Record'!B26) -> 10 | E26: =C26-D26 -> 6 | F26: =D26/C26 -> 0.625
B27: 14 | C27: =COUNTIFS(Master!C:C,'Weekly Record'!B27) -> 14 | D27: =SUMIFS(Master!V:V, Master!C:C,'Weekly Record'!B27) -> 8 | E27: =C27-D27 -> 6 | F27: =D27/C27 -> 0.57142857
B28: 15 | C28: =COUNTIFS(Master!C:C,'Weekly Record'!B28) -> 16 | D28: =SUMIFS(Master!V:V, Master!C:C,'Weekly Record'!B28) -> 8 | E28: =C28-D28 -> 8 | F28: =D28/C28 -> 0.5
B29: 16 | C29: =COUNTIFS(Master!C:C,'Weekly Record'!B29) -> 16 | D29: =SUMIFS(Master!V:V, Master!C:C,'Weekly Record'!B29) -> 6 | E29: =C29-D29 -> 10 | F29: =D29/C29 -> 0.375
B30: 17 | C30: =COUNTIFS(Master!C:C,'Weekly Record'!B30) -> 16 | D30: =SUMIFS(Master!V:V, Master!C:C,'Weekly Record'!B30) -> 10 | E30: =C30-D30 -> 6 | F30: =D30/C30 -> 0.625
B31: 18
B33: ATS
B34: Week | C34: Games | D34: Wins | E34: Losses | F34: %
B35: {=_xlfn.UNIQUE(_xlfn._xlws.FILTER(Master!C9:C1000,NOT(ISBLANK(Master!C9:C1000))))} -> 6 | C35: =COUNTIFS(Master!C:C,'Weekly Record'!B35) -> 15 | D35: =SUMIFS(Master!AB:AB, Master!C:C,'Weekly Record'!B35) -> 0 | E35: =C35-D35 -> 15 | F35: =D35/C35 -> 0
B36: 7 | C36: =COUNTIFS(Master!C:C,'Weekly Record'!B36) -> 15 | D36: =SUMIFS(Master!AB:AB, Master!C:C,'Weekly Record'!B36) -> 0 | E36: =C36-D36 -> 15 | F36: =D36/C36 -> 0
B37: 8 | C37: =COUNTIFS(Master!C:C,'Weekly Record'!B37) -> 13 | D37: =SUMIFS(Master!AB:AB, Master!C:C,'Weekly Record'!B37) -> 0 | E37: =C37-D37 -> 13 | F37: =D37/C37 -> 0
B38: 9 | C38: =COUNTIFS(Master!C:C,'Weekly Record'!B38) -> 14 | D38: =SUMIFS(Master!AB:AB, Master!C:C,'Weekly Record'!B38) -> 0 | E38: =C38-D38 -> 14 | F38: =D38/C38 -> 0
B39: 10 | C39: =COUNTIFS(Master!C:C,'Weekly Record'!B39) -> 14 | D39: =SUMIFS(Master!AB:AB, Master!C:C,'Weekly Record'!B39) -> 0 | E39: =C39-D39 -> 14 | F39: =D39/C39 -> 0
B40: 11 | C40: =COUNTIFS(Master!C:C,'Weekly Record'!B40) -> 15 | D40: =SUMIFS(Master!AB:AB, Master!C:C,'Weekly Record'!B40) -> 7 | E40: =C40-D40 -> 8 | F40: =D40/C40 -> 0.46666667
B41: 12 | C41: =COUNTIFS(Master!C:C,'Weekly Record'!B41) -> 14 | D41: =SUMIFS(Master!AB:AB, Master!C:C,'Weekly Record'!B41) -> 7 | E41: =C41-D41 -> 7 | F41: =D41/C41 -> 0.5
B42: 13 | C42: =COUNTIFS(Master!C:C,'Weekly Record'!B42) -> 16 | D42: =SUMIFS(Master!AB:AB, Master!C:C,'Weekly Record'!B42) -> 8 | E42: =C42-D42 -> 8 | F42: =D42/C42 -> 0.5
...

Sheet Week 6
B2: Correct | C2: 9
B3: Games | C3: 15
B4: % | C4: 0.6
F6: Probabilities | J6: Results | M6: home_epa | P6: away_epa
B7: season | C7: week | D7: home_team | E7: away_team | F7: prob_home | G7: home_team_ml | H7: prob_away | I7: away_team_ml | J7: pred | K7: winner | L7: correct? | M7: EPA_O_Play | N7: EPA_D_Play | O7: EPA_ST_Play | P7: EPA_O_Play | Q7: EPA_D_Play | R7: EPA_ST_Play
B8: 2025 | C8: 6 | D8: NYG | E8: PHI | F8: 0.28413917 | G8: +251 | H8: 0.71586083 | I8: -251 | J8: PHI | K8: NYG | L8: =IF(K8=J8,1,0) -> 0 | M8: 0.25124221 | N8: 0.066168526 | O8: -0.027362438 | P8: -0.066168526 | Q8: -0.25124221 | R8: 0.027362438
B9: 2025 | C9: 6 | D9: NYJ | E9: DEN | F9: 0.30012096 | G9: +233 | H9: 0.69987904 | I9: -233 | J9: DEN | K9: DEN | L9: =IF(K9=J9,1,0) -> 1 | M9: -0.43215489 | N9: 0.16995373 | O9: 0.34083964 | P9: -0.16995373 | Q9: 0.43215489 | R9: -0.34083964
B10: 2025 | C10: 6 | D10: BAL | E10: LA | F10: 0.53913174 | G10: -116 | H10: 0.46086826 | I10: +116 | J10: BAL | K10: LA | L10: =IF(K10=J10,1,0) -> 0 | M10: -0.29375997 | N10: -0.015975545 | O10: 0.37059372 | P10: 0.015975545 | Q10: 0.29375997 | R10: -0.37059372
B11: 2025 | C11: 6 | D11: CAR | E11: DAL | F11: 0.49133873 | G11: +103 | H11: 0.50866127 | I11: -103 | J11: DAL | K11: CAR | L11: =IF(K11=J11,1,0) -> 0 | M11: 0.17789871 | N11: -0.2027874 | O11: 0.024269279 | P11: 0.2027874 | Q11: -0.17789871 | R11: -0.024269279
B12: 2025 | C12: 6 | D12: IND | E12: ARI | F12: 0.58161291 | G12: -139 | H12: 0.41838709 | I12: +139 | J12: IND | K12: IND | L12: =IF(K12=J12,1,0) -> 1 | M12: 0.15875688 | N12: -0.073672771 | O12: -0.062292337 | P12: 0.073672771 | Q12: -0.15875688 | R12: 0.062292337
B13: 2025 | C13: 6 | D13: JAX | E13: SEA | F13: 0.46542939 | G13: +114 | H13: 0.53457061 | I13: -114 | J13: SEA | K13: SEA | L13: =IF(K13=J13,1,0) -> 1 | M13: -0.082264423 | N13: -0.020928413 | O13: -0.20806897 | P13: 0.020928413 | Q13: 0.082264423 | R13: 0.20806897
B14: 2025 | C14: 6 | D14: MIA | E14: LAC | F14: 0.4933361 | G14: +102 | H14: 0.5066639 | I14: -102 | J14: LAC | K14: LAC | L14: =IF(K14=J14,1,0) -> 1 | M14: 0.038278063 | N14: -0.0617472 | O14: -0.013840508 | P14: 0.0617472 | Q14: -0.038278063 | R14: 0.013840508
B15: 2025 | C15: 6 | D15: NO | E15: NE | F15: 0.39499877 | G15: +153 | H15: 0.60500123 | I15: -153 | J15: NE | K15: NE | L15: =IF(K15=J15,1,0) -> 1 | M15: -0.073139174 | N15: -0.13044801 | O15: 0.13509109 | P15: 0.13044801 | Q15: 0.073139174 | R15: -0.13509109
B16: 2025 | C16: 6 | D16: PIT | E16: CLE | F16: 0.71805668 | G16: -254 | H16: 0.28194332 | I16: +254 | J16: PIT | K16: PIT | L16: =IF(K16=J16,1,0) -> 1 | M16: 0.095861427 | N16: 0.13702202 | O16: -0.14666659 | P16: -0.13702202 | Q16: -0.095861427 | R16: 0.14666659
B17: 2025 | C17: 6 | D17: LV | E17: TEN | F17: 0.60215188 | G17: -151 | H17: 0.39784812 | I17: +151 | J17: LV | K17: LV | L17: =IF(K17=J17,1,0) -> 1 | M17: -0.097661511 | N17: 0.24401585 | O17: 0.19498157 | P17: -0.24401585 | Q17: 0.097661511 | R17: -0.19498157
B18: 2025 | C18: 6 | D18: GB | E18: CIN | F18: 0.72152836 | G18: -259 | H18: 0.27847164 | I18: +259 | J18: GB | K18: GB | L18: =IF(K18=J18,1,0) -> 1 | M18: 0.21342839 | N18: -0.10244938 | O18: 0.089890928 | P18: 0.10244938 | Q18: -0.21342839 | R18: -0.089890928
B19: 2025 | C19: 6 | D19: TB | E19: SF | F19: 0.59882672 | G19: -149 | H19: 0.40117328 | I19: +149 | J19: TB | K19: TB | L19: =IF(K19=J19,1,0) -> 1 | M19: 0.24584 | N19: 0.11939343 | O19: -0.28655228 | P19: -0.11939343 | Q19: -0.24584 | R19: 0.28655228
B20: 2025 | C20: 6 | D20: KC | E20: DET | F20: 0.36153707 | G20: +176 | H20: 0.63846293 | I20: -176 | J20: DET | K20: KC | L20: =IF(K20=J20,1,0) -> 0 | M20: 0.31075544 | N20: -0.08266475 | O20: -0.0042046241 | P20: 0.08266475 | Q20: -0.31075544 | R20: 0.0042046241
B21: 2025 | C21: 6 | D21: ATL | E21: BUF | F21: 0.31839251 | G21: +214 | H21: 0.68160749 | I21: -214 | J21: BUF | K21: ATL | L21: =IF(K21=J21,1,0) -> 0 | M21: 0.10814126 | N21: 0.10416144 | O21: -0.1186255 | P21: -0.10416144 | Q21: -0.10814126 | R21: 0.1186255
B22: 2025 | C22: 6 | D22: WAS | E22: CHI | F22: 0.73154658 | G22: -272 | H22: 0.26845342 | I22: +272 | J22: WAS | K22: CHI | L22: =IF(K22=J22,1,0) -> 0 | M22: 0.018111467 | N22: -0.1277509 | O22: 0.071527021 | P22: 0.1277509 | Q22: -0.018111467 | R22: -0.071527021

Sheet Week 7
B2: Correct | C2: =SUM($L$8:$L$22) -> 12
B3: Games | C3: =COUNTA($L$8:$L$23) -> 15
B4: % | C4: =C2/C3 -> 0.8
F6: Probabilities | J6: Results | N6: home_epa | Q6: away_epa
B7: season | C7: week | D7: home_team | E7: away_team | F7: prob_home | G7: home_team_ml | H7: prob_away | I7: away_team_ml | J7: pred | K7: winner | L7: correct? | M7: spread | N7: EPA_O_Play | O7: EPA_D_Play | P7: EPA_ST_Play | Q7: EPA_O_Play | R7: EPA_D_Play | S7: EPA_ST_Play
B8: 2025 | C8: 7 | D8: CIN | E8: PIT | F8: 0.48091506 | G8: +107 | H8: 0.51908494 | I8: -107 | J8: PIT | K8: CIN | L8: 0 | M8: -1.4250698 | N8: 0.28925643 | O8: -0.27371408 | P8: -0.076034888 | Q8: 0.27371408 | R8: -0.28925643 | S8: 0.076034888
B9: 2025 | C9: 7 | D9: JAX | E9: LA | F9: 0.46977703 | G9: +112 | H9: 0.53022297 | I9: -112 | J9: LA | K9: LA | L9: 1 | M9: 1.409425 | N9: -0.1461088 | O9: -0.23843634 | P9: -0.20178508 | Q9: 0.23843634 | R9: 0.1461088 | S9: 0.20178508
B10: 2025 | C10: 7 | D10: CHI | E10: NO | F10: 0.58504581 | G10: -140 | H10: 0.41495419 | I10: +140 | J10: CHI | K10: CHI | L10: 1 | M10: 2.0776658 | N10: 0.01348116 | O10: 0.22400876 | P10: 0.19784313 | Q10: -0.22400876 | R10: -0.01348116 | S10: -0.19784313
B11: 2025 | C11: 7 | D11: CLE | E11: MIA | F11: 0.33682566 | G11: +196 | H11: 0.66317434 | I11: -196 | J11: MIA | K11: CLE | L11: 0 | M11: -5.310912 | N11: -0.017893693 | O11: 0.51155989 | P11: 0.063372169 | Q11: -0.51155989 | R11: 0.017893693 | S11: -0.063372169
B12: 2025 | C12: 7 | D12: KC | E12: LV | F12: 0.76251043 | G12: -321 | H12: 0.23748957 | I12: +321 | J12: KC | K12: KC | L12: 1 | M12: 10.944503 | N12: 0.2171731 | O12: 0.62946069 | P12: -0.24452791 | Q12: -0.62946069 | R12: -0.2171731 | S12: 0.24452791
B13: 2025 | C13: 7 | D13: MIN | E13: PHI | F13: 0.46008668 | G13: +117 | H13: 0.53991332 | I13: -117 | J13: PHI | K13: PHI | L13: 1 | M13: -3.3049392 | N13: -0.088495227 | O13: -0.20847946 | P13: 0.33452468 | Q13: 0.20847946 | R13: 0.088495227 | S13: -0.33452468
B14: 2025 | C14: 7 | D14: NYJ | E14: CAR | F14: 0.43942513 | G14: +127 | H14: 0.56057487 | I14: -127 | J14: CAR | K14: CAR | L14: 1 | M14: -0.38674877 | N14: -0.26674719 | O14: 0.085645286 | P14: -0.11531259 | Q14: -0.085645286 | R14: 0.26674719 | S14: 0.11531259
B15: 2025 | C15: 7 | D15: TEN | E15: NE | F15: 0.31228555 | G15: +220 | H15: 0.68771445 | I15: -220 | J15: NE | K15: NE | L15: 1 | M15: -8.9711202 | N15: -0.28472243 | O15: -0.24146947 | P15: 0.26711339 | Q15: 0.24146947 | R15: 0.28472243 | S15: -0.26711339
B16: 2025 | C16: 7 | D16: DEN | E16: NYG | F16: 0.74988507 | G16: -299 | H16: 0.25011493 | I16: +299 | J16: DEN | K16: DEN | L16: 1 | M16: 11.01286 | N16: 0.11573301 | O16: -0.19457486 | P16: 0.097547495 | Q16: 0.19457486 | R16: -0.11573301 | S16: -0.097547495
B17: 2025 | C17: 7 | D17: LAC | E17: IND | F17: 0.4904864 | G17: +103 | H17: 0.5095136 | I17: -103 | J17: IND | K17: IND | L17: 1 | M17: 1.4672085 | N17: 0.096067357 | O17: -0.44475957 | P17: -0.15667809 | Q17: 0.44475957 | R17: -0.096067357 | S17: 0.15667809
B18: 2025 | C18: 7 | D18: ARI | E18: GB | F18: 0.42954545 | G18: +132 | H18: 0.57045455 | I18: -132 | J18: GB | K18: GB | L18: 1 | M18: -1.7804052 | N18: -0.0025914829 | O18: -0.11835686 | P18: 0.052370644 | Q18: 0.11835686 | R18: 0.0025914829 | S18: -0.052370644
B19: 2025 | C19: 7 | D19: DAL | E19: WAS | F19: 0.45455863 | G19: +119 | H19: 0.54544137 | I19: -119 | J19: WAS | K19: DAL | L19: 0 | M19: -4.5381075 | N19: 0.15809155 | O19: 0.19612538 | P19: 0.031338125 | Q19: -0.19612538 | R19: -0.15809155 | S19: -0.031338125
B20: 2025 | C20: 7 | D20: SF | E20: ATL | F20: 0.50845245 | G20: -103 | H20: 0.49154755 | I20: +103 | J20: SF | K20: SF | L20: 1 | M20: 2.2762753 | N20: 0.0394085 | O20: 0.12123582 | P20: 0.039254677 | Q20: -0.12123582 | R20: -0.0394085 | S20: -0.039254677
B21: 2025 | C21: 7 | D21: DET | E21: TB | F21: 0.58751521 | G21: -142 | H21: 0.41248479 | I21: +142 | J21: DET | K21: DET | L21: 1 | M21: 1.7082762 | N21: -0.099057456 | O21: 0.35557553 | P21: -0.024791638 | Q21: -0.35557553 | R21: 0.099057456 | S21: 0.024791638
B22: 2025 | C22: 7 | D22: SEA | E22: HOU | F22: 0.61141525 | G22: -157 | H22: 0.38858475 | I22: +157 | J22: SEA | K22: SEA | L22: 1 | M22: 3.772163 | N22: -0.23093883 | O22: 0.32778671 | P22: 0.043519257 | Q22: -0.32778671 | R22: 0.23093883 | S22: -0.043519257

Sheet Week 8
B2: Correct | C2: =SUM($L$8:$L$20) -> 11
B3: Games | C3: =COUNTA($L$8:$L$21) -> 13
B4: % | C4: =C2/C3 -> 0.84615385
F6: Probabilities | J6: Results | N6: home_epa | Q6: away_epa
B7: season | C7: week | D7: home_team | E7: away_team | F7: prob_home | G7: home_team_ml | H7: prob_away | I7: away_team_ml | J7: pred | K7: winner | L7: correct? | M7: spread | N7: EPA_O_Play | O7: EPA_D_Play | P7: EPA_ST_Play | Q7: EPA_O_Play | R7: EPA_D_Play | S7: EPA_ST_Play
B8: 2025 | C8: 8 | D8: LAC | E8: MIN | F8: 0.536 | G8: -120 | H8: 0.464 | I8: +120 | J8: LAC | K8: LAC | L8: 1 | M8: 0.3 | N8: 0.20573016 | O8: 0.33306915 | P8: -0.013063612 | Q8: -0.33306915 | R8: -0.20573016 | S8: 0.013063612
B9: 2025 | C9: 8 | D9: ATL | E9: MIA | F9: 0.586 | G9: -144 | H9: 0.414 | I9: +144 | J9: ATL | K9: MIA | L9: 0 | M9: 1.8 | N9: -0.30089874 | O9: -0.13344567 | P9: -0.14619972 | Q9: 0.13344567 | R9: 0.30089874 | S9: 0.14619972
B10: 2025 | C10: 8 | D10: BAL | E10: CHI | F10: 0.61263916 | G10: -158 | H10: 0.38736084 | I10: +158 | J10: BAL | K10: BAL | L10: 1 | M10: 4.6 | N10: 0.20792883 | O10: -0.017090889 | P10: 0.084218423 | Q10: 0.017090889 | R10: -0.20792883 | S10: -0.084218423
B11: 2025 | C11: 8 | D11: CAR | E11: BUF | F11: 0.347 | G11: +204 | H11: 0.653 | I11: -204 | J11: BUF | K11: BUF | L11: 1 | M11: -8.9 | N11: -0.31306085 | O11: -0.32291098 | P11: 0.048412263 | Q11: 0.32291098 | R11: 0.31306085 | S11: -0.048412263
B12: 2025 | C12: 8 | D12: CIN | E12: NYJ | F12: 0.604 | G12: -148 | H12: 0.396 | I12: +148 | J12: CIN | K12: NYJ | L12: 0 | M12: 2.4368333 | N12: 0.25655905 | O12: -0.31294929 | P12: 0.062102087 | Q12: 0.31294929 | R12: -0.25655905 | S12: -0.062102087
B13: 2025 | C13: 8 | D13: HOU | E13: SF | F13: 0.536 | G13: -116 | H13: 0.464 | I13: +116 | J13: HOU | K13: HOU | L13: 1 | M13: 4 | N13: 0.21049607 | O13: 0.036765984 | P13: -0.11886264 | Q13: -0.036765984 | R13: -0.21049607 | S13: 0.11886264
B14: 2025 | C14: 8 | D14: NE | E14: CLE | F14: 0.7986187 | G14: -396 | H14: 0.2013813 | I14: +396 | J14: NE | K14: NE | L14: 1 | M14: 9.4 | N14: 0.073067423 | O14: 0.31074229 | P14: 0.096539397 | Q14: -0.31074229 | R14: -0.073067423 | S14: -0.096539397
B15: 2025 | C15: 8 | D15: PHI | E15: NYG | F15: 0.698 | G15: -227 | H15: 0.302 | I15: +227 | J15: PHI | K15: PHI | L15: 1 | M15: 8.292967 | N15: 0.38337591 | O15: -0.041866832 | P15: -0.021435082 | Q15: 0.041866832 | R15: -0.38337591 | S15: 0.021435082
B16: 2025 | C16: 8 | D16: NO | E16: TB | F16: 0.282 | G16: +260 | H16: 0.718 | I16: -260 | J16: TB | K16: TB | L16: 1 | M16: -7.4 | N16: -0.46523213 | O16: 0.16694887 | P16: -0.19439544 | Q16: -0.16694887 | R16: 0.46523213 | S16: 0.19439544
B17: 2025 | C17: 8 | D17: DEN | E17: DAL | F17: 0.578 | G17: -139 | H17: 0.422 | I17: +139 | J17: DEN | K17: DEN | L17: 1 | M17: 6.3 | N17: 0.37087668 | O17: -0.044475715 | P17: 0.017721645 | Q17: 0.044475715 | R17: -0.37087668 | S17: -0.017721645
B18: 2025 | C18: 8 | D18: IND | E18: TEN | F18: 0.864 | G18: -646 | H18: 0.136 | I18: +646 | J18: IND | K18: IND | L18: 1 | M18: 13 | N18: 0.34562467 | O18: 0.036582743 | P18: 0.26308648 | Q18: -0.036582743 | R18: -0.34562467 | S18: -0.26308648
B19: 2025 | C19: 8 | D19: PIT | E19: GB | F19: 0.413 | G19: +138 | H19: 0.587 | I19: -138 | J19: GB | K19: GB | L19: 1 | M19: -3.5 | N19: -0.12485238 | O19: -0.32949493 | P19: 0.42716217 | Q19: 0.32949493 | R19: 0.12485238 | S19: -0.42716217
B20: 2025 | C20: 8 | D20: KC | E20: WAS | F20: 0.617 | G20: -160 | H20: 0.383 | I20: +160 | J20: KC | K20: KC | L20: 1 | M20: 4.5 | N20: 0.26601786 | O20: 0.1654421 | P20: -0.18689229 | Q20: -0.1654421 | R20: -0.26601786 | S20: 0.18689229

Sheet Week 9
B2: Correct | C2: =SUM($L$8:$L$20) -> 7
B3: Games | C3: =COUNTA($L$8:$L$21) -> 14
B4: % | C4: =C2/C3 -> 0.5
F6: Probabilities | J6: Results | N6: home_epa | Q6: away_epa
B7: season | C7: week | D7: home_team | E7: away_team | F7: prob_home | G7: home_team_ml | H7: prob_away | I7: away_team_ml | J7: pred | K7: winner | L7: correct? | M7: spread | N7: EPA_O_Play | O7: EPA_D_Play | P7: EPA_ST_Play | Q7: EPA_O_Play | R7: EPA_D_Play | S7: EPA_ST_Play
B8: 2025 | C8: 9 | D8: MIA | E8: BAL | F8: 0.44668876 | G8: +123 | H8: 0.55331124 | I8: -123 | J8: BAL | K8: BAL | L8: 1 | M8: -1.8151554 | N8: -0.22526313 | O8: -0.16305417 | P8: -0.01721597 | Q8: 0.16305417 | R8: 0.22526313 | S8: 0.01721597
B9: 2025 | C9: 9 | D9: CIN | E9: CHI | F9: 0.60003242 | G9: -150 | H9: 0.39996758 | I9: +150 | J9: CIN | K9: CHI | L9: 0 | M9: 5.2136732 | N9: 0.18499579 | O9: -0.43041533 | P9: 0.35861015 | Q9: 0.43041533 | R9: -0.18499579 | S9: -0.35861015
B10: 2025 | C10: 9 | D10: DET | E10: MIN | F10: 0.69773234 | G10: -230 | H10: 0.30226766 | I10: +230 | J10: DET | K10: MIN | L10: 0 | M10: 5.1113256 | N10: -0.038011411 | O10: 0.018339883 | P10: -0.1744423 | Q10: -0.018339883 | R10: 0.038011411 | S10: 0.1744423
B11: 2025 | C11: 9 | D11: GB | E11: CAR | F11: 0.7107726 | G11: -245 | H11: 0.2892274 | I11: +245 | J11: GB | K11: CAR | L11: 0 | M11: 8.8238014 | N11: -0.0015043539 | O11: -0.073761737 | P11: -0.0084348623 | Q11: 0.073761737 | R11: 0.0015043539 | S11: 0.0084348623
B12: 2025 | C12: 9 | D12: HOU | E12: DEN | F12: 0.49332374 | G12: +102 | H12: 0.50667626 | I12: -102 | J12: DEN | K12: DEN | L12: 1 | M12: -1.8833132 | N12: -0.19600596 | O12: 0.10367945 | P12: 0.19043292 | Q12: -0.10367945 | R12: 0.19600596 | S12: -0.19043292
B13: 2025 | C13: 9 | D13: NE | E13: ATL | F13: 0.61882511 | G13: -162 | H13: 0.38117489 | I13: +162 | J13: NE | K13: NE | L13: 1 | M13: 4.6932068 | N13: 0.01246086 | O13: -0.034125898 | P13: 0.067735273 | Q13: 0.034125898 | R13: -0.01246086 | S13: -0.067735273
B14: 2025 | C14: 9 | D14: NYG | E14: SF | F14: 0.48417671 | G14: +106 | H14: 0.51582329 | I14: -106 | J14: SF | K14: SF | L14: 1 | M14: -2.1777639 | N14: 0.15103745 | O14: -0.24087369 | P14: -0.23305713 | Q14: 0.24087369 | R14: -0.15103745 | S14: 0.23305713
B15: 2025 | C15: 9 | D15: PIT | E15: IND | F15: 0.36042278 | G15: +177 | H15: 0.63957722 | I15: -177 | J15: IND | K15: PIT | L15: 0 | M15: -3.7411637 | N15: -0.10357435 | O15: 0.094617844 | P15: 0.25383404 | Q15: -0.094617844 | R15: 0.10357435 | S15: -0.25383404
B16: 2025 | C16: 9 | D16: TEN | E16: LAC | F16: 0.24911204 | G16: +301 | H16: 0.75088796 | I16: -301 | J16: LAC | K16: LAC | L16: 1 | M16: -10.468339 | N16: -0.24477963 | O16: -0.041809082 | P16: 0.18575405 | Q16: 0.041809082 | R16: 0.24477963 | S16: -0.18575405
B17: 2025 | C17: 9 | D17: LA | E17: NO | F17: 0.75454089 | G17: -307 | H17: 0.24545911 | I17: +307 | J17: LA | K17: LA | L17: 1 | M17: 9.4243349 | N17: 0.25134553 | O17: 0.31206388 | P17: -0.28692413 | Q17: -0.31206388 | R17: -0.25134553 | S17: 0.28692413
B18: 2025 | C18: 9 | D18: LV | E18: JAX | F18: 0.39584202 | G18: +152 | H18: 0.60415798 | I18: -152 | J18: JAX | K18: JAX | L18: 1 | M18: 0.7817882 | N18: 0.14785485 | O18: -0.10314792 | P18: -0.13232757 | Q18: 0.10314792 | R18: -0.14785485 | S18: 0.13232757
B19: 2025 | C19: 9 | D19: BUF | E19: KC | F19: 0.49275135 | G19: +102 | H19: 0.50724865 | I19: -102 | J19: KC | K19: BUF | L19: 0 | M19: 0.058964153 | N19: 0.21633625 | O19: 0.0022891673 | P19: -0.29582127 | Q19: -0.0022891673 | R19: -0.21633625 | S19: 0.29582127
... B21: 2025 | C21: 9 | D21: DAL | E21: ARI | F21: 0.55292721 | G21: -123 | H21: 0.44707279 | I21: +123 | J21: DAL | K21: ARI | L21: 0 | M21: -1.4444053 | N21: -0.1342727 | O21: -0.11058104 | P21: 0.12445244 | Q21: 0.11058104 | R21: 0.1342727 | S21: -0.12445244

Sheet Week 10
B2: Correct | C2: =SUM($L$8:$L$20) -> 10
B3: Games | C3: =COUNTA($L$8:$L$21) -> 14
B4: % | C4: =C2/C3 -> 0.71428571
F6: Probabilities | J6: Results | N6: home_epa | Q6: away_epa
B7: season | C7: week | D7: home_team | E7: away_team | F7: prob_home | G7: home_team_ml | H7: prob_away | I7: away_team_ml | J7: pred | K7: winner | L7: correct? | M7: spread | N7: EPA_O_Play | O7: EPA_D_Play | P7: EPA_ST_Play | Q7: EPA_O_Play | R7: EPA_D_Play | S7: EPA_ST_Play
B8: 2025 | C8: 10 | D8: DEN | E8: LV | F8: 0.76598917 | G8: -327 | H8: 0.23401083 | I8: 327 | J8: DEN | K8: DEN | L8: 1 | M8: 8.1813164 | N8: -0.30538679 | O8: 0.3926294 | P8: 0.065123501 | Q8: -0.3926294 | R8: 0.30538679 | S8: -0.065123501
B9: 2025 | C9: 10 | D9: IND | E9: ATL | F9: 0.71280531 | G9: -248 | H9: 0.28719469 | I9: 248 | J9: IND | K9: IND | L9: 1 | M9: 7.3657236 | N9: 0.16381766 | O9: 0.023067955 | P9: -0.12090954 | Q9: -0.023067955 | R9: -0.16381766 | S9: 0.12090954
B10: 2025 | C10: 10 | D10: CAR | E10: NO | F10: 0.70590823 | G10: -240 | H10: 0.29409177 | I10: 240 | J10: CAR | K10: NO | L10: 0 | M10: 3.9583235 | N10: -0.30006108 | O10: -0.14284027 | P10: 0.33378386 | Q10: 0.14284027 | R10: 0.30006108 | S10: -0.33378386
B11: 2025 | C11: 10 | D11: CHI | E11: NYG | F11: 0.59132934 | G11: -144 | H11: 0.40867066 | I11: 144 | J11: CHI | K11: CHI | L11: 1 | M11: 7.4688557 | N11: 0.076580394 | O11: 0.0054572396 | P11: -0.01544331 | Q11: -0.0054572396 | R11: -0.076580394 | S11: 0.01544331
B12: 2025 | C12: 10 | D12: HOU | E12: JAX | F12: 0.62953559 | G12: -169 | H12: 0.37046441 | I12: 169 | J12: HOU | K12: HOU | L12: 1 | M12: 5.7488555 | N12: 0.11924662 | O12: 0.17853055 | P12: -0.35401583 | Q12: -0.17853055 | R12: -0.11924662 | S12: 0.35401583
B13: 2025 | C13: 10 | D13: MIA | E13: BUF | F13: 0.26774883 | G13: 273 | H13: 0.73225117 | I13: -273 | J13: BUF | K13: MIA | L13: 0 | M13: -9.2184474 | N13: 0.31231633 | O13: 0.069657404 | P13: 0.10761982 | Q13: -0.069657404 | R13: -0.31231633 | S13: -0.10761982
B14: 2025 | C14: 10 | D14: MIN | E14: BAL | F14: 0.44864183 | G14: 122 | H14: 0.55135817 | I14: -122 | J14: BAL | K14: BAL | L14: 1 | M14: 0.75145619 | N14: -0.07083939 | O14: -0.010264242 | P14: -0.13717836 | Q14: 0.010264242 | R14: 0.07083939 | S14: 0.13717836
B15: 2025 | C15: 10 | D15: NYJ | E15: CLE | F15: 0.63435392 | G15: -173 | H15: 0.36564608 | I15: 173 | J15: NYJ | K15: NYJ | L15: 1 | M15: 4.8957802 | N15: -0.24411571 | O15: 0.043361252 | P15: 0.46754145 | Q15: -0.043361252 | R15: 0.24411571 | S15: -0.46754145
B16: 2025 | C16: 10 | D16: TB | E16: NE | F16: 0.54090552 | G16: -117 | H16: 0.45909448 | I16: 117 | J16: TB | K16: NE | L16: 0 | M16: 5.7404372 | N16: 0.067429122 | O16: -0.19361868 | P16: -0.032632189 | Q16: 0.19361868 | R16: -0.067429122 | S16: 0.032632189
B17: 2025 | C17: 10 | D17: SEA | E17: ARI | F17: 0.6036118 | G17: -152 | H17: 0.3963882 | I17: 152 | J17: SEA | K17: SEA | L17: 1 | M17: 2.2381512 | N17: 0.087747591 | O17: 0.22612943 | P17: 0.19157505 | Q17: -0.22612943 | R17: -0.087747591 | S17: -0.19157505
B18: 2025 | C18: 10 | D18: SF | E18: LA | F18: 0.37630173 | G18: 165 | H18: 0.62369827 | I18: -165 | J18: LA | K18: LA | L18: 1 | M18: -6.0450952 | N18: 0.12942703 | O18: -0.4141483 | P18: -0.029721847 | Q18: 0.4141483 | R18: -0.12942703 | S18: 0.029721847
B19: 2025 | C19: 10 | D19: WAS | E19: DET | F19: 0.32988907 | G19: 203 | H19: 0.67011093 | I19: -203 | J19: DET | K19: DET | L19: 1 | M19: -8.9053153 | N19: 0.21370635 | O19: -0.49142589 | P19: -0.050597828 | Q19: 0.49142589 | R19: -0.21370635 | S19: 0.050597828
... B21: 2025 | C21: 10 | D21: GB | E21: PHI | F21: 0.54854361 | G21: -121 | H21: 0.45145639 | I21: 121 | J21: GB | K21: PHI | L21: 0 | M21: 1.9739159 | N21: -0.15282585 | O21: 0.069291402 | P21: -0.03648334 | Q21: -0.069291402 | R21: 0.15282585 | S21: 0.03648334
B24: season | C24: week | D24: home_team | E24: away_team | F24: prob_home | G24: pred_home_ml_viz | H24: prob_away | I24: pred_away_ml_viz | J24: home_moneyline | K24: away_moneyline | L24: pred | M24: winner | N24: correct? | O24: spread_line | P24: pred_spread | Q24: total_line | R24: home_team_EPA_O_Play | S24: home_team_EPA_D_Play | T24: home_team_EPA_ST_Play | U24: away_team_EPA_O_Play | V24: away_team_EPA_D_Play | W24: away_team_EPA_ST_Play
B25: 2025 | C25: 10 | D25: DEN | E25: LV | F25: 0.76598917 | G25: -327 | H25: 0.23401083 | I25: 327 | J25: -500 | K25: 380 | L25: DEN | M25: DEN | N25: 1 | O25: 9.5 | P25: 8.1813164 | Q25: 42.5 | R25: -0.30538679 | S25: 0.3926294 | T25: 0.065123501 | U25: -0.3926294 | V25: 0.30538679 | W25: -0.065123501
B26: 2025 | C26: 10 | D26: IND | E26: ATL | F26: 0.71280531 | G26: -248 | H26: 0.28719469 | I26: 248 | J26: -310 | K26: 250 | L26: IND | M26: IND | N26: 1 | O26: 6.5 | P26: 7.3657236 | Q26: 48.5 | R26: 0.16381766 | S26: 0.023067955 | T26: -0.12090954 | U26: -0.023067955 | V26: -0.16381766 | W26: 0.12090954
B27: 2025 | C27: 10 | D27: CAR | E27: NO | F27: 0.70590823 | G27: -240 | H27: 0.29409177 | I27: 240 | J27: -245 | K27: 200 | L27: CAR | M27: NO | N27: 0 | O27: 5.5 | P27: 3.9583235 | Q27: 38.5 | R27: -0.30006108 | S27: -0.14284027 | T27: 0.33378386 | U27: 0.14284027 | V27: 0.30006108 | W27: -0.33378386
B28: 2025 | C28: 10 | D28: CHI | E28: NYG | F28: 0.59132934 | G28: -144 | H28: 0.40867066 | I28: 144 | J28: -218 | K28: 180 | L28: CHI | M28: CHI | N28: 1 | O28: 4.5 | P28: 7.4688557 | Q28: 45.5 | R28: 0.076580394 | S28: 0.0054572396 | T28: -0.01544331 | U28: -0.0054572396 | V28: -0.076580394 | W28: 0.01544331
B29: 2025 | C29: 10 | D29: HOU | E29: JAX | F29: 0.62953559 | G29: -169 | H29: 0.37046441 | I29: 169 | J29: -105 | K29: -115 | L29: HOU | M29: HOU | N29: 1 | O29: -1.5 | P29: 5.7488555 | Q29: 37.5 | R29: 0.11924662 | S29: 0.17853055 | T29: -0.35401583 | U29: -0.17853055 | V29: -0.11924662 | W29: 0.35401583
B30: 2025 | C30: 10 | D30: MIA | E30: BUF | F30: 0.26774883 | G30: 273 | H30: 0.73225117 | I30: -273 | J30: 350 | K30: -455 | L30: BUF | M30: MIA | N30: 0 | O30: -8.5 | P30: -9.2184474 | Q30: 50.5 | R30: 0.31231633 | S30: 0.069657404 | T30: 0.10761982 | U30: -0.069657404 | V30: -0.31231633 | W30: -0.10761982
B31: 2025 | C31: 10 | D31: MIN | E31: BAL | F31: 0.44864183 | G31: 122 | H31: 0.55135817 | I31: -122 | J31: 190 | K31: -230 | L31: BAL | M31: BAL | N31: 1 | O31: -4.5 | P31: 0.75145619 | Q31: 48.5 | R31: -0.07083939 | S31: -0.010264242 | T31: -0.13717836 | U31: 0.010264242 | V31: 0.07083939 | W31: 0.13717836
B32: 2025 | C32: 10 | D32: NYJ | E32: CLE | F32: 0.63435392 | G32: -173 | H32: 0.36564608 | I32: 173 | J32: 110 | K32: -130 | L32: NYJ | M32: NYJ | N32: 1 | O32: -1.5 | P32: 4.8957802 | Q32: 37.5 | R32: -0.24411571 | S32: 0.043361252 | T32: 0.46754145 | U32: -0.043361252 | V32: 0.24411571 | W32: -0.46754145
B33: 2025 | C33: 10 | D33: TB | E33: NE | F33: 0.54090552 | G33: -117 | H33: 0.45909448 | I33: 117 | J33: -148 | K33: 124 | L33: TB | M33: NE | N33: 0 | O33: 2.5 | P33: 5.7404372 | Q33: 48.5 | R33: 0.067429122 | S33: -0.19361868 | T33: -0.032632189 | U33: 0.19361868 | V33: -0.067429122 | W33: 0.032632189
B34: 2025 | C34: 10 | D34: SEA | E34: ARI | F34: 0.6036118 | G34: -152 | H34: 0.3963882 | I34: 152 | J34: -340 | K34: 270 | L34: SEA | M34: SEA | N34: 1 | O34: 7 | P34: 2.2381512 | Q34: 44.5 | R34: 0.087747591 | S34: 0.22612943 | T34: 0.19157505 | U34: -0.22612943 | V34: -0.087747591 | W34: -0.19157505
B35: 2025 | C35: 10 | D35: SF | E35: LA | F35: 0.37630173 | G35: 165 | H35: 0.62369827 | I35: -165 | J35: 210 | K35: -258 | L35: LA | M35: LA | N35: 1 | O35: -5.5 | P35: -6.0450952 | Q35: 49.5 | R35: 0.12942703 | S35: -0.4141483 | T35: -0.029721847 | U35: 0.4141483 | V35: -0.12942703 | W35: 0.029721847
B36: 2025 | C36: 10 | D36: WAS | E36: DET | F36: 0.32988907 | G36: 203 | H36: 0.67011093 | I36: -203 | J36: 350 | K36: -455 | L36: DET | M36: DET | N36: 1 | O36: -8.5 | P36: -8.9053153 | Q36: 49.5 | R36: 0.21370635 | S36: -0.49142589 | T36: -0.050597828 | U36: 0.49142589 | V36: -0.21370635 | W36: 0.050597828
... B38: 2025 | C38: 10 | D38: GB | E38: PHI | F38: 0.54854361 | G38: -121 | H38: 0.45145639 | I38: 121 | J38: -110 | K38: -110 | L38: GB | M38: PHI | N38: 0 | O38: 1.5 | P38: 1.9739159 | Q38: 45.5 | R38: -0.15282585 | S38: 0.069291402 | T38: -0.03648334 | U38: -0.069291402 | V38: 0.15282585 | W38: 0.03648334

Sheet Week 11
B2: Games | C2: =COUNTA(C9:C24) -> 15
B3: Picks | C3: =SUM(L9:L24) -> 10 | D3: =C3/$C$2 -> 0.66666667
B4: ATS | C4: =SUM(T9:T24) -> 6 | D4: =C4/$C$2 -> 0.4
B5: Total | C5: =SUM(Z9:Z24) -> 7 | D5: =C5/$C$2 -> 0.46666667
F7: Game Picks (Win Prob) | M7: Pred Score (Score Model) | O7: Spread Picks (Score Model) | U7: Total Picks (Score Model) | AA7: home_epa | AD7: away_epa
B8: season | C8: week | D8: home_team | E8: away_team | F8: prob_home | G8: home_team_ml | H8: prob_away | I8: away_team_ml | J8: pred | K8: winner | L8: winner_correct? | M8: home | N8: away | O8: spread_line | P8: pred_spread | Q8: spread_pick | R8: result | S8: spread_result | T8: spread_correct? | U8: total_line | V8: pred_total | W8: total_pick | X8: total | Y8: total_result | Z8: total_correct? | AA8: EPA_O_Play | AB8: EPA_D_Play | AC8: EPA_ST_Play | AD8: EPA_O_Play | AE8: EPA_D_Play | AF8: EPA_ST_Play
B9: 2025 | C9: 11 | D9: NE | E9: NYJ | F9: 0.73413242 | G9: -276 | H9: 0.26586758 | I9: 276 | J9: NE | K9: NE | L9: 1 | M9: 25.528369 | N9: 20.22373 | O9: 12.5 | P9: 5.3046389 | Q9: away | R9: 13 | S9: home | T9: 0 | U9: 43.5 | V9: 45.7521 | W9: over | X9: 41 | Y9: under | Z9: 0 | AA9: 0.13845152 | AB9: 0.08509738 | AC9: -0.025755165 | AD9: -0.08509738 | AE9: -0.13845152 | AF9: 0.025755165
B10: 2025 | C10: 11 | D10: MIA | E10: WAS | F10: 0.52678544 | G10: -111 | H10: 0.47321456 | I10: 111 | J10: MIA | K10: MIA | L10: 1 | M10: 24.527074 | N10: 24.057862 | O10: 2.5 | P10: 0.46921203 | Q10: away | R10: 3 | S10: home | T10: 0 | U10: 47.5 | V10: 48.584937 | W10: over | X10: 29 | Y10: under | Z10: 0 | AA10: -0.0066568373 | AB10: -0.081908561 | AC10: 0.5259428 | AD10: 0.081908561 | AE10: 0.0066568373 | AF10: -0.5259428
B11: 2025 | C11: 11 | D11: ATL | E11: CAR | F11: 0.51452568 | G11: -105 | H11: 0.48547432 | I11: 105 | J11: ATL | K11: CAR | L11: 0 | M11: 22.07165 | N11: 22.122493 | O11: 4.5 | P11: -0.050843241 | Q11: away | R11: -3 | S11: away | T11: 1 | U11: 42.5 | V11: 44.194144 | W11: over | X11: 57 | Y11: over | Z11: 1 | AA11: 0.088263252 | AB11: -0.097721843 | AC11: -0.14740959 | AD11: 0.097721843 | AE11: -0.088263252 | AF11: 0.14740959
B12: 2025 | C12: 11 | D12: BUF | E12: TB | F12: 0.50773179 | G12: -103 | H12: 0.49226821 | I12: 103 | J12: BUF | K12: BUF | L12: 1 | M12: 23.286361 | N12: 23.477927 | O12: 6 | P12: -0.19156609 | Q12: away | R12: 12 | S12: home | T12: 0 | U12: 46.5 | V12: 46.764287 | W12: over | X12: 76 | Y12: over | Z12: 1 | AA12: 0.30272924 | AB12: -0.099317249 | AC12: 0.067811171 | AD12: 0.099317249 | AE12: -0.30272924 | AF12: -0.067811171
B13: 2025 | C13: 11 | D13: JAX | E13: LAC | F13: 0.36620122 | G13: 173 | H13: 0.63379878 | I13: -173 | J13: LAC | K13: JAX | L13: 0 | M13: 21.930669 | N13: 23.731812 | O13: -3 | P13: -1.8011423 | Q13: home | R13: 29 | S13: home | T13: 1 | U13: 43.5 | V13: 45.662481 | W13: over | X13: 41 | Y13: under | Z13: 0 | AA13: 0.13688974 | AB13: 0.47060466 | AC13: -0.067403096 | AD13: -0.47060466 | AE13: -0.13688974 | AF13: 0.067403096
B14: 2025 | C14: 11 | D14: MIN | E14: CHI | F14: 0.44461106 | G14: 124 | H14: 0.55538894 | I14: -124 | J14: CHI | K14: CHI | L14: 1 | M14: 24.368539 | N14: 21.663786 | O14: 3 | P14: 2.7047523 | Q14: away | R14: -2 | S14: away | T14: 1 | U14: 47.5 | V14: 46.032325 | W14: under | X14: 36 | Y14: under | Z14: 1 | AA14: -0.17616986 | AB14: 0.063100866 | AC14: 0.0032722871 | AD14: -0.063100866 | AE14: 0.17616986 | AF14: -0.0032722871
B15: 2025 | C15: 11 | D15: NYG | E15: GB | F15: 0.35652248 | G15: 180 | H15: 0.64347752 | I15: -180 | J15: GB | K15: GB | L15: 1 | M15: 21.472942 | N15: 29.823338 | O15: -7.5 | P15: -8.3503957 | Q15: away | R15: -7 | S15: home | T15: 0 | U15: 41.5 | V15: 51.29628 | W15: over | X15: 47 | Y15: over | Z15: 1 | AA15: 0.13630217 | AB15: -0.33779028 | AC15: 0.013593824 | AD15: 0.33779028 | AE15: -0.13630217 | AF15: -0.013593824
B16: 2025 | C16: 11 | D16: PIT | E16: CIN | F16: 0.48976373 | G16: 104 | H16: 0.51023627 | I16: -104 | J16: CIN | K16: PIT | L16: 0 | M16: 24.412031 | N16: 23.292815 | O16: 5.5 | P16: 1.1192158 | Q16: away | R16: 22 | S16: home | T16: 0 | U16: 48.5 | V16: 47.704846 | W16: under | X16: 46 | Y16: under | Z16: 1 | AA16: 0.18347394 | AB16: 0.17247109 | AC16: -0.06669148 | AD16: -0.17247109 | AE16: -0.18347394 | AF16: 0.06669148
B17: 2025 | C17: 11 | D17: TEN | E17: HOU | F17: 0.29616364 | G17: 237 | H17: 0.70383636 | I17: -237 | J17: HOU | K17: HOU | L17: 1 | M17: 16.862988 | N17: 25.64513 | O17: -5.5 | P17: -8.7821425 | Q17: away | R17: -3 | S17: home | T17: 0 | U17: 37.5 | V17: 42.508118 | W17: over | X17: 29 | Y17: under | Z17: 0 | AA17: -0.096223605 | AB17: 0.065306922 | AC17: 0.084802499 | AD17: -0.065306922 | AE17: 0.096223605 | AF17: -0.084802499
B18: 2025 | C18: 11 | D18: ARI | E18: SF | F18: 0.4802955 | G18: 108 | H18: 0.5197045 | I18: -108 | J18: SF | K18: SF | L18: 1 | M18: 23.546027 | N18: 23.679698 | O18: -3.5 | P18: -0.13367133 | Q18: home | R18: -19 | S18: away | T18: 0 | U18: 48.5 | V18: 47.225725 | W18: under | X18: 63 | Y18: over | Z18: 0 | AA18: -0.00067925453 | AB18: -0.21416486 | AC18: -0.41683269 | AD18: 0.21416486 | AE18: 0.00067925453 | AF18: 0.41683269
B19: 2025 | C19: 11 | D19: LA | E19: SEA | F19: 0.58877447 | G19: -143 | H19: 0.41122553 | I19: 143 | J19: LA | K19: LA | L19: 1 | M19: 26.636651 | N19: 21.599355 | O19: 3 | P19: 5.0372961 | Q19: home | R19: 2 | S19: away | T19: 0 | U19: 49.5 | V19: 48.236005 | W19: under | X19: 40 | Y19: under | Z19: 1 | AA19: -0.1940106 | AB19: 0.189935 | AC19: -0.17548372 | AD19: -0.189935 | AE19: 0.1940106 | AF19: 0.17548372
B20: 2025 | C20: 11 | D20: CLE | E20: BAL | F20: 0.28322852 | G20: 253 | H20: 0.71677148 | I20: -253 | J20: BAL | K20: BAL | L20: 1 | M20: 17.436789 | N20: 24.534227 | O20: -7.5 | P20: -7.0974381 | Q20: home | R20: -7 | S20: home | T20: 1 | U20: 37.5 | V20: 41.971016 | W20: over | X20: 39 | Y20: over | Z20: 1 | AA20: -0.43516581 | AB20: 0.11659462 | AC20: 0.23310184 | AD20: -0.11659462 | AE20: 0.43516581 | AF20: -0.23310184
... B23: 2025 | C23: 11 | D23: LV | E23: DAL | F23: 0.33113716 | G23: 201 | H23: 0.66886284 | I23: -201 | J23: DAL | K23: DAL | L23: 1 | M23: 20.948298 | N23: 24.516146 | O23: -3.5 | P23: -3.5678478 | Q23: away | R23: -17 | S23: away | T23: 1 | U23: 48.5 | V23: 45.464445 | W23: under | X23: 49 | Y23: over | Z23: 0 | AA23: -0.1985623 | AB23: -0.16860405 | AC23: -0.10609831 | AD23: 0.16860405 | AE23: 0.1985623 | AF23: 0.10609831

Sheet Week 12
B2: Games | C2: =COUNTA(C9:C22) -> 14
B3: Picks | C3: =SUM(N9:N22) -> 10 | D3: =C3/$C$2 -> 0.71428571
B4: ATS | C4: =SUM(V9:V22) -> 8 | D4: =C4/$C$2 -> 0.57142857
B5: Total | C5: =SUM(AB9:AB22) -> 7 | D5: =C5/$C$2 -> 0.5
H7: Game Picks (Win Prob) | O7: Pred Score (Score Model) | Q7: Spread Picks (Score Model) | W7: Total Picks (Score Model) | AC7: home_epa | AF7: away_epa
B8: season | C8: week | D8: home_team | E8: away_team | F8: home_score | G8: away_score | H8: prob_home | I8: home_team_ml | J8: prob_away | K8: away_team_ml | L8: pred | M8: winner | N8: winner_correct? | O8: home | P8: away | Q8: spread_line | R8: pred_spread | S8: spread_pick | T8: result | U8: spread_result | V8: spread_correct? | W8: total_line | X8: pred_total | Y8: total_pick | Z8: total | AA8: total_result | AB8: total_correct? | AC8: EPA_O_Play | AD8: EPA_D_Play | AE8: EPA_ST_Play | AF8: EPA_O_Play | AG8: EPA_D_Play | AH8: EPA_ST_Play
B9: 2025 | C9: 12 | D9: HOU | E9: BUF | F9: 23 | G9: 19 | H9: 0.41641097 | I9: +140 | J9: 0.58358903 | K9: -140 | L9: BUF | M9: HOU | N9: 0 | O9: 22.310796 | P9: 26.77923 | Q9: -5.5 | R9: -4.4684347 | S9: home | T9: 4 | U9: home | V9: 1 | W9: 43.5 | X9: 49.090026 | Y9: over | Z9: 42 | AA9: under | AB9: 0 | AC9: -0.077266307 | AD9: 0.16421366 | AE9: -0.092399334 | AF9: -0.16421366 | AG9: 0.077266307 | AH9: 0.092399334
B10: 2025 | C10: 12 | D10: BAL | E10: NYJ | F10: 23 | G10: 10 | H10: 0.68542228 | I10: -217 | J10: 0.31457772 | K10: +217 | L10: BAL | M10: BAL | N10: 1 | O10: 25.833018 | P10: 17.239148 | Q10: 14 | R10: 8.5938705 | S10: away | T10: 13 | U10: away | V10: 1 | W10: 44.5 | X10: 43.072166 | Y10: under | Z10: 33 | AA10: under | AB10: 1 | AC10: 0.055789142 | AD10: 0.1999663 | AE10: -0.017604619 | AF10: -0.1999663 | AG10: -0.055789142 | AH10: 0.017604619
B11: 2025 | C11: 12 | D11: CHI | E11: PIT | F11: 31 | G11: 28 | H11: 0.57957288 | I11: -137 | J11: 0.42042712 | K11: +137 | L11: CHI | M11: CHI | N11: 1 | O11: 25.384505 | P11: 23.313587 | Q11: 3 | R11: 2.0709178 | S11: away | T11: 3 | U11: away | V11: 1 | W11: 46.5 | X11: 48.698092 | Y11: over | Z11: 59 | AA11: over | AB11: 1 | AC11: 0.011751022 | AD11: -0.048218843 | AE11: 0.12702806 | AF11: 0.048218843 | AG11: -0.011751022 | AH11: -0.12702806
B12: 2025 | C12: 12 | D12: CIN | E12: NE | F12: 20 | G12: 26 | H12: 0.35067814 | I12: +185 | J12: 0.64932186 | K12: -185 | L12: NE | M12: NE | N12: 1 | O12: 23.468714 | P12: 26.734601 | Q12: -7.5 | R12: -3.2658869 | S12: home | T12: -6 | U12: home | V12: 1 | W12: 50.5 | X12: 50.203315 | Y12: under | Z12: 46 | AA12: under | AB12: 1 | AC12: -0.17502532 | AD12: -0.022934188 | AE12: 0.019687261 | AF12: 0.022934188 | AG12: 0.17502532 | AH12: -0.019687261
B13: 2025 | C13: 12 | D13: DET | E13: NYG | F13: 34 | G13: 27 | H13: 0.70151946 | I13: -235 | J13: 0.29848054 | K13: +235 | L13: DET | M13: DET | N13: 1 | O13: 29.019062 | P13: 20.794064 | Q13: 14 | R13: 8.2249977 | S13: away | T13: 7 | U13: away | V13: 1 | W13: 50.5 | X13: 49.813127 | Y13: under | Z13: 61 | AA13: over | AB13: 0 | AC13: 0.15461845 | AD13: -0.14523478 | AE13: 0.13269214 | AF13: 0.14523478 | AG13: -0.15461845 | AH13: -0.13269214
B14: 2025 | C14: 12 | D14: GB | E14: MIN | F14: 23 | G14: 6 | H14: 0.67902861 | I14: -211 | J14: 0.32097139 | K14: +211 | L14: GB | M14: GB | N14: 1 | O14: 23.214139 | P14: 20.322641 | Q14: 6.5 | R14: 2.8914973 | S14: away | T14: 17 | U14: home | V14: 0 | W14: 41.5 | X14: 43.53678 | Y14: over | Z14: 29 | AA14: under | AB14: 0 | AC14: 0.055030324 | AD14: 0.42938007 | AE14: 0.049084961 | AF14: -0.42938007 | AG14: -0.055030324 | AH14: -0.049084961
B15: 2025 | C15: 12 | D15: KC | E15: IND | F15: 23 | G15: 20 | H15: 0.48672609 | I15: +105 | J15: 0.51327391 | K15: -105 | L15: IND | M15: KC | N15: 0 | O15: 23.394954 | P15: 25.226613 | Q15: 3.5 | R15: -1.8316586 | S15: away | T15: 3 | U15: away | V15: 1 | W15: 50.5 | X15: 48.621566 | Y15: under | Z15: 43 | AA15: under | AB15: 1 | AC15: 0.020509374 | AD15: 0.018942168 | AE15: -0.12783007 | AF15: -0.018942168 | AG15: -0.020509374 | AH15: 0.12783007
B16: 2025 | C16: 12 | D16: TEN | E16: SEA | F16: 24 | G16: 30 | H16: 0.23620152 | I16: +323 | J16: 0.76379848 | K16: -323 | L16: SEA | M16: SEA | N16: 1 | O16: 17.810645 | P16: 26.003828 | Q16: -12.5 | R16: -8.1931823 | S16: home | T16: -6 | U16: home | V16: 1 | W16: 41.5 | X16: 43.814473 | Y16: over | Z16: 54 | AA16: over | AB16: 1 | AC16: -0.0096211052 | AD16: -0.27772254 | AE16: 0.03311822 | AF16: 0.27772254 | AG16: 0.0096211052 | AH16: -0.03311822
B17: 2025 | C17: 12 | D17: ARI | E17: JAX | F17: 24 | G17: 27 | H17: 0.46416166 | I17: +115 | J17: 0.53583834 | K17: -115 | L17: JAX | M17: JAX | N17: 1 | O17: 22.314164 | P17: 23.35 | Q17: -2.5 | R17: -1.0358368 | S17: home | T17: -3 | U17: away | V17: 0 | W17: 47.5 | X17: 45.664164 | Y17: under | Z17: 51 | AA17: over | AB17: 0 | AC17: -0.13217131 | AD17: 0.17871148 | AE17: -0.23651325 | AF17: -0.17871148 | AG17: 0.13217131 | AH17: 0.23651325
B18: 2025 | C18: 12 | D18: LV | E18: CLE | F18: 10 | G18: 24 | H18: 0.51782158 | I18: -107 | J18: 0.48217842 | K18: +107 | L18: LV | M18: CLE | N18: 0 | O18: 20.171215 | P18: 16.879107 | Q18: 3 | R18: 3.2921078 | S18: home | T18: -14 | U18: away | V18: 0 | W18: 35.5 | X18: 37.050322 | Y18: over | Z18: 34 | AA18: under | AB18: 0 | AC18: -0.33489239 | AD18: 0.22228737 | AE18: -0.09006681 | AF18: -0.22228737 | AG18: 0.33489239 | AH18: 0.09006681
B19: 2025 | C19: 12 | D19: DAL | E19: PHI | F19: 24 | G19: 21 | H19: 0.47087485 | I19: +112 | J19: 0.52912515 | K19: -112 | L19: PHI | M19: DAL | N19: 0 | O19: 22.441663 | P19: 25.696632 | Q19: -3 | R19: -3.254969 | S19: away | T19: 3 | U19: home | V19: 0 | W19: 47.5 | X19: 48.138294 | Y19: over | Z19: 45 | AA19: under | AB19: 0 | AC19: -0.024016536 | AD19: -0.0031687721 | AE19: 0.25749626 | AF19: 0.0031687721 | AG19: 0.024016536 | AH19: -0.25749626
B20: 2025 | C20: 12 | D20: NO | E20: ATL | F20: 10 | G20: 24 | H20: 0.33749899 | I20: +196 | J20: 0.66250101 | K20: -196 | L20: ATL | M20: ATL | N20: 1 | O20: 17.70399 | P20: 22.578308 | Q20: 1.5 | R20: -4.8743184 | S20: away | T20: -14 | U20: away | V20: 1 | W20: 41.5 | X20: 40.282298 | Y20: under | Z20: 34 | AA20: under | AB20: 1 | AC20: -0.23330636 | AD20: 0.13419797 | AE20: -0.33283915 | AF20: -0.13419797 | AG20: 0.23330636 | AH20: 0.33283915
B21: 2025 | C21: 12 | D21: LA | E21: TB | F21: 34 | G21: 7 | H21: 0.60571599 | I21: -153 | J21: 0.39428401 | K21: +153 | L21: LA | M21: LA | N21: 1 | O21: 24.899717 | P21: 21.52489 | Q21: 7 | R21: 3.3748265 | S21: away | T21: 27 | U21: home | V21: 0 | W21: 49.5 | X21: 46.424607 | Y21: under | Z21: 41 | AA21: under | AB21: 1 | AC21: 0.076005033 | AD21: 0.39518528 | AE21: 0.05407331 | AF21: -0.39518528 | AG21: -0.076005033 | AH21: -0.05407331
B22: 2025 | C22: 12 | D22: SF | E22: CAR | F22: 20 | G22: 9 | H22: 0.66176739 | I22: -195 | J22: 0.33823261 | K22: +195 | L22: SF | M22: SF | N22: 1 | O22: 29.439876 | P22: 23.536853 | Q22: 7.5 | R22: 5.9030228 | S22: away | T22: 11 | U22: home | V22: 0 | W22: 48.5 | X22: 52.976729 | Y22: over | Z22: 29 | AA22: under | AB22: 0 | AC22: -0.0013478714 | AD22: 0.21901258 | AE22: 0.20380351 | AF22: -0.21901258 | AG22: 0.0013478714 | AH22: -0.20380351

Sheet Week 13
B2: Games | C2: =COUNTA($C$9:$C$24) -> 16
B3: Picks | C3: =SUM(N9:$N$24) -> 10 | D3: =C3/$C$2 -> 0.625
B4: ATS | C4: =SUM(V9:$V$24) -> 10 | D4: =C4/$C$2 -> 0.625
B5: Total | C5: =SUM(AB9:$AB$24) -> 8 | D5: =C5/$C$2 -> 0.5
H7: Game Picks (Win Prob) | O7: Pred Score (Score Model) | Q7: Spread Picks (Score Model) | W7: Total Picks (Score Model) | AC7: home_epa | AF7: away_epa
B8: season | C8: week | D8: home_team | E8: away_team | F8: home_score | G8: away_score | H8: prob_home | I8: home_team_ml | J8: prob_away | K8: away_team_ml | L8: pred | M8: winner | N8: winner_correct? | O8: home | P8: away | Q8: spread_line | R8: pred_spread | S8: spread_pick | T8: result | U8: spread_result | V8: spread_correct? | W8: total_line | X8: pred_total | Y8: total_pick | Z8: total | AA8: total_result | AB8: total_correct? | AC8: EPA_O_Play | AD8: EPA_D_Play | AE8: EPA_ST_Play | AF8: EPA_O_Play | AG8: EPA_D_Play | AH8: EPA_ST_Play
B9: 2025 | C9: 13 | D9: DET | E9: GB | F9: 24 | G9: 31 | H9: 0.48253295 | I9: +107 | J9: 0.51746705 | K9: -107 | L9: GB | M9: GB | N9: 1 | O9: 25.529234 | P9: 25.607126 | Q9: 2.5 | R9: -0.077892432 | S9: away | T9: -7 | U9: away | V9: 1 | W9: 48.5 | X9: 51.13636 | Y9: over | Z9: 55 | AA9: over | AB9: 1 | AC9: 0.048194106 | AD9: -0.31817717 | AE9: 0.052845548 | AF9: 0.31817717 | AG9: -0.048194106 | AH9: -0.052845548
B10: 2025 | C10: 13 | D10: DAL | E10: KC | F10: 31 | G10: 28 | H10: 0.46143532 | I10: +116 | J10: 0.53856468 | K10: -116 | L10: KC | M10: DAL | N10: 0 | O10: 23.335192 | P10: 27.117306 | Q10: -3.5 | R10: -3.7821139 | S10: away | T10: 3 | U10: home | V10: 0 | W10: 53.5 | X10: 50.452497 | Y10: under | Z10: 59 | AA10: over | AB10: 0 | AC10: 0.27415718 | AD10: -0.17532253 | AE10: -0.0073952505 | AF10: 0.17532253 | AG10: -0.27415718 | AH10: 0.0073952505
B11: 2025 | C11: 13 | D11: BAL | E11: CIN | F11: 14 | G11: 32 | H11: 0.6362911 | I11: -174 | J11: 0.3637089 | K11: +174 | L11: BAL | M11: CIN | N11: 0 | O11: 25.279016 | P11: 20.504198 | Q11: 7 | R11: 4.774818 | S11: away | T11: -18 | U11: away | V11: 1 | W11: 52.5 | X11: 45.783215 | Y11: under | Z11: 46 | AA11: under | AB11: 1 | AC11: -0.33492179 | AD11: -0.019006772 | AE11: -0.16997031 | AF11: 0.019006772 | AG11: 0.33492179 | AH11: 0.16997031
B12: 2025 | C12: 13 | D12: PHI | E12: CHI | F12: 15 | G12: 24 | H12: 0.56753267 | I12: -131 | J12: 0.43246733 | K12: +131 | L12: PHI | M12: CHI | N12: 0 | O12: 24.962502 | P12: 18.993511 | Q12: 7 | R12: 5.9689908 | S12: away | T12: -9 | U12: away | V12: 1 | W12: 43.5 | X12: 43.956013 | Y12: over | Z12: 39 | AA12: under | AB12: 0 | AC12: -0.038964977 | AD12: -0.042160286 | AE12: -0.17308134 | AF12: 0.042160286 | AG12: 0.038964977 | AH12: 0.17308134
B13: 2025 | C13: 13 | D13: CAR | E13: LA | F13: 31 | G13: 28 | H13: 0.28542976 | I13: +250 | J13: 0.71457024 | K13: -250 | L13: LA | M13: CAR | N13: 0 | O13: 21.008246 | P13: 27.144542 | Q13: -10 | R13: -6.1362957 | S13: home | T13: 3 | U13: home | V13: 1 | W13: 44.5 | X13: 48.152788 | Y13: over | Z13: 59 | AA13: over | AB13: 1 | AC13: 0.19092291 | AD13: -0.14862052 | AE13: -0.12567352 | AF13: 0.14862052 | AG13: -0.19092291 | AH13: 0.12567352
B14: 2025 | C14: 13 | D14: CLE | E14: SF | F14: 8 | G14: 26 | H14: 0.29341197 | I14: +240 | J14: 0.70658803 | K14: -240 | L14: SF | M14: SF | N14: 1 | O14: 19.126577 | P14: 24.024826 | Q14: -5.5 | R14: -4.8982491 | S14: home | T14: -18 | U14: away | V14: 0 | W14: 35.5 | X14: 43.151403 | Y14: over | Z14: 34 | AA14: under | AB14: 0 | AC14: -0.23705799 | AD14: -0.025767024 | AE14: -0.4000305 | AF14: 0.025767024 | AG14: 0.23705799 | AH14: 0.4000305
B15: 2025 | C15: 13 | D15: IND | E15: HOU | F15: 16 | G15: 20 | H15: 0.640658 | I15: -178 | J15: 0.359342 | K15: +178 | L15: IND | M15: HOU | N15: 0 | O15: 26.080701 | P15: 21.401255 | Q15: 3 | R15: 4.6794463 | S15: home | T15: -4 | U15: away | V15: 0 | W15: 44.5 | X15: 47.481956 | Y15: over | Z15: 36 | AA15: under | AB15: 0 | AC15: -0.034005245 | AD15: -0.030582845 | AE15: -0.13908773 | AF15: 0.030582845 | AG15: 0.034005245 | AH15: 0.13908773
B16: 2025 | C16: 13 | D16: MIA | E16: NO | F16: 21 | G16: 17 | H16: 0.71553633 | I16: -251 | J16: 0.28446367 | K16: +251 | L16: MIA | M16: MIA | N16: 1 | O16: 26.918814 | P16: 17.904846 | Q16: 5.5 | R16: 9.0139675 | S16: home | T16: 4 | U16: away | V16: 0 | W16: 41.5 | X16: 44.82366 | Y16: over | Z16: 38 | AA16: under | AB16: 0 | AC16: -0.13490427 | AD16: 0.14688459 | AE16: 0.01837379 | AF16: -0.14688459 | AG16: 0.13490427 | AH16: -0.01837379
B17: 2025 | C17: 13 | D17: NYJ | E17: ATL | F17: 27 | G17: 24 | H17: 0.46351677 | I17: +115 | J17: 0.53648323 | K17: -115 | L17: ATL | M17: NYJ | N17: 0 | O17: 24.5201 | P17: 24.577626 | Q17: -3 | R17: -0.057525987 | S17: home | T17: 3 | U17: home | V17: 1 | W17: 38.5 | X17: 49.097726 | Y17: over | Z17: 51 | AA17: over | AB17: 1 | AC17: 0.023049905 | AD17: -0.18087268 | AE17: 0.46029137 | AF17: 0.18087268 | AG17: -0.023049905 | AH17: -0.46029137
B18: 2025 | C18: 13 | D18: TB | E18: ARI | F18: 20 | G18: 17 | H18: 0.54317327 | I18: -118 | J18: 0.45682673 | K18: +118 | L18: TB | M18: TB | N18: 1 | O18: 22.252294 | P18: 19.46532 | Q18: 4.5 | R18: 2.7869738 | S18: away | T18: 3 | U18: away | V18: 1 | W18: 44.5 | X18: 41.717615 | Y18: under | Z18: 37 | AA18: under | AB18: 1 | AC18: -0.029960443 | AD18: 0.026304464 | AE18: 0.35829971 | AF18: -0.026304464 | AG18: 0.029960443 | AH18: -0.35829971
B19: 2025 | C19: 13 | D19: TEN | E19: JAX | F19: 3 | G19: 25 | H19: 0.31470374 | I19: +217 | J19: 0.68529626 | K19: -217 | L19: JAX | M19: JAX | N19: 1 | O19: 19.256245 | P19: 24.747671 | Q19: -6 | R19: -5.491425 | S19: home | T19: -22 | U19: away | V19: 0 | W19: 42.5 | X19: 44.003916 | Y19: over | Z19: 28 | AA19: under | AB19: 0 | AC19: -0.37743313 | AD19: -0.0099263052 | AE19: -0.081854213 | AF19: 0.0099263052 | AG19: 0.37743313 | AH19: 0.081854213
